Creating test database for alias 'default'...
..F...F..F...F..E..E....EEE
======================================================================
ERROR: test_can_create_order (backend.tests.models.test_order_model.OrderTests)
----------------------------------------------------------------------
Traceback (most recent call last):
  File "/usr/local/lib/python3.7/site-packages/django/db/backends/utils.py", line 84, in _execute
    return self.cursor.execute(sql, params)
psycopg2.errors.NotNullViolation: null value in column "shipping_method_id" violates not-null constraint
DETAIL:  Failing row contains (1, 2020-02-26 14:45:18.143547+00, 2, 11, null, 0).


The above exception was the direct cause of the following exception:

Traceback (most recent call last):
  File "/app/backend/tests/models/test_order_model.py", line 39, in test_can_create_order
    cart = Cart.objects.create(user=user, address=address)
  File "/usr/local/lib/python3.7/site-packages/django/db/models/manager.py", line 82, in manager_method
    return getattr(self.get_queryset(), name)(*args, **kwargs)
  File "/usr/local/lib/python3.7/site-packages/django/db/models/query.py", line 422, in create
    obj.save(force_insert=True, using=self.db)
  File "/usr/local/lib/python3.7/site-packages/django/db/models/base.py", line 741, in save
    force_update=force_update, update_fields=update_fields)
  File "/usr/local/lib/python3.7/site-packages/django/db/models/base.py", line 779, in save_base
    force_update, using, update_fields,
  File "/usr/local/lib/python3.7/site-packages/django/db/models/base.py", line 870, in _save_table
    result = self._do_insert(cls._base_manager, using, fields, update_pk, raw)
  File "/usr/local/lib/python3.7/site-packages/django/db/models/base.py", line 908, in _do_insert
    using=using, raw=raw)
  File "/usr/local/lib/python3.7/site-packages/django/db/models/manager.py", line 82, in manager_method
    return getattr(self.get_queryset(), name)(*args, **kwargs)
  File "/usr/local/lib/python3.7/site-packages/django/db/models/query.py", line 1186, in _insert
    return query.get_compiler(using=using).execute_sql(return_id)
  File "/usr/local/lib/python3.7/site-packages/django/db/models/sql/compiler.py", line 1335, in execute_sql
    cursor.execute(sql, params)
  File "/usr/local/lib/python3.7/site-packages/django/db/backends/utils.py", line 67, in execute
    return self._execute_with_wrappers(sql, params, many=False, executor=self._execute)
  File "/usr/local/lib/python3.7/site-packages/django/db/backends/utils.py", line 76, in _execute_with_wrappers
    return executor(sql, params, many, context)
  File "/usr/local/lib/python3.7/site-packages/django/db/backends/utils.py", line 84, in _execute
    return self.cursor.execute(sql, params)
  File "/usr/local/lib/python3.7/site-packages/django/db/utils.py", line 89, in __exit__
    raise dj_exc_value.with_traceback(traceback) from exc_value
  File "/usr/local/lib/python3.7/site-packages/django/db/backends/utils.py", line 84, in _execute
    return self.cursor.execute(sql, params)
django.db.utils.IntegrityError: null value in column "shipping_method_id" violates not-null constraint
DETAIL:  Failing row contains (1, 2020-02-26 14:45:18.143547+00, 2, 11, null, 0).


======================================================================
ERROR: test_can_create_product (backend.tests.models.test_product_model.ProductTests)
----------------------------------------------------------------------
Traceback (most recent call last):
  File "/app/backend/tests/models/test_product_model.py", line 18, in test_can_create_product
    product = Product.objects.create(title=self.title, description=self.description, featured=self.featured)
  File "/usr/local/lib/python3.7/site-packages/django/db/models/manager.py", line 82, in manager_method
    return getattr(self.get_queryset(), name)(*args, **kwargs)
  File "/usr/local/lib/python3.7/site-packages/django/db/models/query.py", line 420, in create
    obj = self.model(**kwargs)
  File "/usr/local/lib/python3.7/site-packages/django/db/models/base.py", line 501, in __init__
    raise TypeError("%s() got an unexpected keyword argument '%s'" % (cls.__name__, kwarg))
TypeError: Product() got an unexpected keyword argument 'featured'

======================================================================
ERROR: test_can_create_variant (backend.tests.models.test_variant_model.VariantTests)
----------------------------------------------------------------------
Traceback (most recent call last):
  File "/app/backend/tests/models/test_variant_model.py", line 29, in test_can_create_variant
    image=self.image)
  File "/usr/local/lib/python3.7/site-packages/django/db/models/manager.py", line 82, in manager_method
    return getattr(self.get_queryset(), name)(*args, **kwargs)
  File "/usr/local/lib/python3.7/site-packages/django/db/models/query.py", line 420, in create
    obj = self.model(**kwargs)
  File "/usr/local/lib/python3.7/site-packages/django/db/models/base.py", line 501, in __init__
    raise TypeError("%s() got an unexpected keyword argument '%s'" % (cls.__name__, kwarg))
TypeError: Product() got an unexpected keyword argument 'image'

======================================================================
ERROR: backend.tests.models.test_cart_model (unittest.loader._FailedTest)
----------------------------------------------------------------------
ImportError: Failed to import test module: backend.tests.models.test_cart_model
Traceback (most recent call last):
  File "/usr/local/lib/python3.7/unittest/loader.py", line 436, in _find_test_path
    module = self._get_module_from_name(name)
  File "/usr/local/lib/python3.7/unittest/loader.py", line 377, in _get_module_from_name
    __import__(name)
  File "/app/backend/tests/models/test_cart_model.py", line 2, in <module>
    from utils.user import create_user
ModuleNotFoundError: No module named 'utils'


======================================================================
ERROR: backend.tests.models.test_image_model (unittest.loader._FailedTest)
----------------------------------------------------------------------
ImportError: Failed to import test module: backend.tests.models.test_image_model
Traceback (most recent call last):
  File "/usr/local/lib/python3.7/unittest/loader.py", line 436, in _find_test_path
    module = self._get_module_from_name(name)
  File "/usr/local/lib/python3.7/unittest/loader.py", line 377, in _get_module_from_name
    __import__(name)
  File "/app/backend/tests/models/test_image_model.py", line 7, in <module>
    from backend.test.utils.category import create_product
ModuleNotFoundError: No module named 'backend.test'


======================================================================
FAIL: test_can_delete_image (backend.tests.models.test_banner_model.BannerTests)
----------------------------------------------------------------------
Traceback (most recent call last):
  File "/app/backend/tests/models/test_banner_model.py", line 47, in test_can_delete_image
    self.assertFalse(check_file_exists_on_model(self.banner, settings.BANNER_IMAGES_DIR, self.image_name, settings.MEDIA_DIR))
AssertionError: True is not false

======================================================================
FAIL: test_can_delete_image (backend.tests.models.test_carousel_model.CarouselTests)
----------------------------------------------------------------------
Traceback (most recent call last):
  File "/app/backend/tests/models/test_carousel_model.py", line 47, in test_can_delete_image
    self.assertFalse(check_file_exists_on_model(self.carousel, settings.CAROUSEL_IMAGES_DIR, self.image_name, settings.MEDIA_DIR))
AssertionError: True is not false

======================================================================
FAIL: test_can_delete_image (backend.tests.models.test_category_model.CategoryTests)
----------------------------------------------------------------------
Traceback (most recent call last):
  File "/app/backend/tests/models/test_category_model.py", line 38, in test_can_delete_image
    self.category, settings.CATEGORY_IMAGES_DIR, self.image_name, settings.MEDIA_DIR))
AssertionError: True is not false

======================================================================
FAIL: test_can_delete_image (backend.tests.models.test_landing_model.LandingBannerTests)
----------------------------------------------------------------------
Traceback (most recent call last):
  File "/app/backend/tests/models/test_landing_model.py", line 47, in test_can_delete_image
    self.assertFalse(check_file_exists_on_model(self.landing, settings.LANDING_IMAGES_DIR, self.image_name, settings.MEDIA_DIR))
AssertionError: True is not false

----------------------------------------------------------------------
Ran 27 tests in 0.707s

FAILED (failures=4, errors=5)
Destroying test database for alias 'default'...
